Workbook

Sheet Proyección Mayores 70
A1: Proyección de Hogares Unipersonales de Mayores de 70 años
A2: Fórmula: Proyección hogares unipersonales × % Mayores de 70 por sexo
A3: Provincia | B3: Sexo | C3: 2024 | D3: 2025 | E3: 2026 | F3: 2027 | G3: 2028 | H3: 2029 | I3: 2030 | J3: 2031 | K3: 2032 | L3: 2033 | M3: 2034 | N3: 2035 | O3: 2036 | P3: 2037 | Q3: 2038 | R3: 2039
A4: Total Nacional | B4: Ambos Sexos | C4: ='proyección hogares'!Q10*'provincia (%)'!K9 -> 1866665.9 | D4: ='proyección hogares'!P10*'provincia (%)'!K9 -> 1927634.1 | E4: ='proyección hogares'!O10*'provincia (%)'!K9 -> 1988710.6 | F4: ='proyección hogares'!N10*'provincia (%)'!K9 -> 2048040.3 | G4: ='proyección hogares'!M10*'provincia (%)'!K9 -> 2106779.4 | H4: ='proyección hogares'!L10*'provincia (%)'!K9 -> 2165338.3 | I4: ='proyección hogares'!K10*'provincia (%)'!K9 -> 2220294.3 | J4: ='proyección hogares'!J10*'provincia (%)'!K9 -> 2272439.9 | K4: ='proyección hogares'!I10*'provincia (%)'!K9 -> 2323035 | L4: ='proyección hogares'!H10*'provincia (%)'!K9 -> 2372917.6 | M4: ='proyección hogares'!G10*'provincia (%)'!K9 -> 2420590 | N4: ='proyección hogares'!F10*'provincia (%)'!K9 -> 2467569.5 | O4: ='proyección hogares'!E10*'provincia (%)'!K9 -> 2514057.4 | P4: ='proyección hogares'!D10*'provincia (%)'!K9 -> 2559825.3 | Q4: ='proyección hogares'!C10*'provincia (%)'!K9 -> 2604790.5 | R4: ='proyección hogares'!B10*'provincia (%)'!K9 -> 2648134.9
B5: Hombre | C5: ='proyección hogares'!Q10*'provincia (%)'!K10 -> 1072416.3 | D5: ='proyección hogares'!P10*'provincia (%)'!K10 -> 1107443.1 | E5: ='proyección hogares'!O10*'provincia (%)'!K10 -> 1142532.1 | F5: ='proyección hogares'!N10*'provincia (%)'!K10 -> 1176617.5 | G5: ='proyección hogares'!M10*'provincia (%)'!K10 -> 1210363.7 | H5: ='proyección hogares'!L10*'provincia (%)'!K10 -> 1244006.3 | I5: ='proyección hogares'!K10*'provincia (%)'!K10 -> 1275579 | J5: ='proyección hogares'!J10*'provincia (%)'!K10 -> 1305537.1 | K5: ='proyección hogares'!I10*'provincia (%)'!K10 -> 1334604.4 | L5: ='proyección hogares'!H10*'provincia (%)'!K10 -> 1363262.4 | M5: ='proyección hogares'!G10*'provincia (%)'!K10 -> 1390650.7 | N5: ='proyección hogares'!F10*'provincia (%)'!K10 -> 1417640.8 | O5: ='proyección hogares'!E10*'provincia (%)'!K10 -> 1444348.5 | P5: ='proyección hogares'!D10*'provincia (%)'!K10 -> 1470642.6 | Q5: ='proyección hogares'!C10*'provincia (%)'!K10 -> 1496475.5 | R5: ='proyección hogares'!B10*'provincia (%)'!K10 -> 1521377.3
B6: Mujer | C6: ='proyección hogares'!Q10*'provincia (%)'!K11 -> 2554791.3 | D6: ='proyección hogares'!P10*'provincia (%)'!K11 -> 2638234.9 | E6: ='proyección hogares'!O10*'provincia (%)'!K11 -> 2721826.5 | F6: ='proyección hogares'!N10*'provincia (%)'!K11 -> 2803027.4 | G6: ='proyección hogares'!M10*'provincia (%)'!K11 -> 2883420.1 | H6: ='proyección hogares'!L10*'provincia (%)'!K11 -> 2963565.9 | I6: ='proyección hogares'!K10*'provincia (%)'!K11 -> 3038780.8 | J6: ='proyección hogares'!J10*'provincia (%)'!K11 -> 3110149.5 | K6: ='proyección hogares'!I10*'provincia (%)'!K11 -> 3179395.8 | L6: ='proyección hogares'!H10*'provincia (%)'!K11 -> 3247667 | M6: ='proyección hogares'!G10*'provincia (%)'!K11 -> 3312913.3 | N6: ='proyección hogares'!F10*'provincia (%)'!K11 -> 3377211.3 | O6: ='proyección hogares'!E10*'provincia (%)'!K11 -> 3440836.5 | P6: ='proyección hogares'!D10*'provincia (%)'!K11 -> 3503476.3 | Q6: ='proyección hogares'!C10*'provincia (%)'!K11 -> 3565017.3 | R6: ='proyección hogares'!B10*'provincia (%)'!K11 -> 3624340.1
A7: Málaga | B7: Ambos Sexos | C7: ='proyección hogares'!Q24*'provincia (%)'!K133 -> 55285.224 | D7: ='proyección hogares'!P24*'provincia (%)'!K133 -> 57665.024 | E7: ='proyección hogares'!O24*'provincia (%)'!K133 -> 60052.779 | F7: ='proyección hogares'!N24*'provincia (%)'!K133 -> 62350.742 | G7: ='proyección hogares'!M24*'provincia (%)'!K133 -> 64591.873 | H7: ='proyección hogares'!L24*'provincia (%)'!K133 -> 66740.371 | I7: ='proyección hogares'!K24*'provincia (%)'!K133 -> 68738.265 | J7: ='proyección hogares'!J24*'provincia (%)'!K133 -> 70606.017 | K7: ='proyección hogares'!I24*'provincia (%)'!K133 -> 72412.675 | L7: ='proyección hogares'!H24*'provincia (%)'!K133 -> 74178.984 | M7: ='proyección hogares'!G24*'provincia (%)'!K133 -> 75850.1 | N7: ='proyección hogares'!F24*'provincia (%)'!K133 -> 77481.151 | O7: ='proyección hogares'!E24*'provincia (%)'!K133 -> 79083.502 | P7: ='proyección hogares'!D24*'provincia (%)'!K133 -> 80654.879 | Q7: ='proyección hogares'!C24*'provincia (%)'!K133 -> 82199.831 | R7: ='proyección hogares'!B24*'provincia (%)'!K133 -> 83697.897
B8: Hombre | C8: ='proyección hogares'!Q24*'provincia (%)'!K134 -> 34792.121 | D8: ='proyección hogares'!P24*'provincia (%)'!K134 -> 36289.777 | E8: ='proyección hogares'!O24*'provincia (%)'!K134 -> 37792.441 | F8: ='proyección hogares'!N24*'provincia (%)'!K134 -> 39238.596 | G8: ='proyección hogares'!M24*'provincia (%)'!K134 -> 40648.986 | H8: ='proyección hogares'!L24*'provincia (%)'!K134 -> 42001.079 | I8: ='proyección hogares'!K24*'provincia (%)'!K134 -> 43258.395 | J8: ='proyección hogares'!J24*'provincia (%)'!K134 -> 44433.809 | K8: ='proyección hogares'!I24*'provincia (%)'!K134 -> 45570.776 | L8: ='proyección hogares'!H24*'provincia (%)'!K134 -> 46682.35 | M8: ='proyección hogares'!G24*'provincia (%)'!K134 -> 47734.018 | N8: ='proyección hogares'!F24*'provincia (%)'!K134 -> 48760.471 | O8: ='proyección hogares'!E24*'provincia (%)'!K134 -> 49768.863 | P8: ='proyección hogares'!D24*'provincia (%)'!K134 -> 50757.763 | Q8: ='proyección hogares'!C24*'provincia (%)'!K134 -> 51730.033 | R8: ='proyección hogares'!B24*'provincia (%)'!K134 -> 52672.796
B9: Mujer | C9: ='proyección hogares'!Q24*'provincia (%)'!K135 -> 75670.78 | D9: ='proyección hogares'!P24*'provincia (%)'!K135 -> 78928.093 | E9: ='proyección hogares'!O24*'provincia (%)'!K135 -> 82196.295 | F9: ='proyección hogares'!N24*'provincia (%)'!K135 -> 85341.596 | G9: ='proyección hogares'!M24*'provincia (%)'!K135 -> 88409.109 | H9: ='proyección hogares'!L24*'provincia (%)'!K135 -> 91349.831 | I9: ='proyección hogares'!K24*'provincia (%)'!K135 -> 94084.418 | J9: ='proyección hogares'!J24*'provincia (%)'!K135 -> 96640.873 | K9: ='proyección hogares'!I24*'provincia (%)'!K135 -> 99113.709 | L9: ='proyección hogares'!H24*'provincia (%)'!K135 -> 101531.32 | M9: ='proyección hogares'!G24*'provincia (%)'!K135 -> 103818.63 | N9: ='proyección hogares'!F24*'provincia (%)'!K135 -> 106051.1 | O9: ='proyección hogares'!E24*'provincia (%)'!K135 -> 108244.3 | P9: ='proyección hogares'!D24*'provincia (%)'!K135 -> 110395.1 | Q9: ='proyección hogares'!C24*'provincia (%)'!K135 -> 112509.72 | R9: ='proyección hogares'!B24*'provincia (%)'!K135 -> 114560.18
A10: Jaén | B10: Ambos Sexos | C10: ='proyección hogares'!Q31*'provincia (%)'!K113 -> 30775.98 | D10: ='proyección hogares'!P31*'provincia (%)'!K113 -> 31663.861 | E10: ='proyección hogares'!O31*'provincia (%)'!K113 -> 32514.258 | F10: ='proyección hogares'!N31*'provincia (%)'!K113 -> 33272.684 | G10: ='proyección hogares'!M31*'provincia (%)'!K113 -> 34073.826 | H10: ='proyección hogares'!L31*'provincia (%)'!K113 -> 34908.531 | I10: ='proyección hogares'!K31*'provincia (%)'!K113 -> 35657.804 | J10: ='proyección hogares'!J31*'provincia (%)'!K113 -> 36313.799 | K10: ='proyección hogares'!I31*'provincia (%)'!K113 -> 36947.129 | L10: ='proyección hogares'!H31*'provincia (%)'!K113 -> 37623.174 | M10: ='proyección hogares'!G31*'provincia (%)'!K113 -> 38263.042 | N10: ='proyección hogares'!F31*'provincia (%)'!K113 -> 38859.322 | O10: ='proyección hogares'!E31*'provincia (%)'!K113 -> 39454.294 | P10: ='proyección hogares'!D31*'provincia (%)'!K113 -> 40058.856 | Q10: ='proyección hogares'!C31*'provincia (%)'!K113 -> 40635.957 | R10: ='proyección hogares'!B31*'provincia (%)'!K113 -> 41220.469
B11: Hombre | C11: ='proyección hogares'!Q31*'provincia (%)'!K114 -> 17458.873 | D11: ='proyección hogares'!P31*'provincia (%)'!K114 -> 17962.558 | E11: ='proyección hogares'!O31*'provincia (%)'!K114 -> 18444.979 | F11: ='proyección hogares'!N31*'provincia (%)'!K114 -> 18875.226 | G11: ='proyección hogares'!M31*'provincia (%)'!K114 -> 19329.705 | H11: ='proyección hogares'!L31*'provincia (%)'!K114 -> 19803.224 | I11: ='proyección hogares'!K31*'provincia (%)'!K114 -> 20228.278 | J11: ='proyección hogares'!J31*'provincia (%)'!K114 -> 20600.417 | K11: ='proyección hogares'!I31*'provincia (%)'!K114 -> 20959.697 | L11: ='proyección hogares'!H31*'provincia (%)'!K114 -> 21343.211 | M11: ='proyección hogares'!G31*'provincia (%)'!K114 -> 21706.2 | N11: ='proyección hogares'!F31*'provincia (%)'!K114 -> 22044.463 | O11: ='proyección hogares'!E31*'provincia (%)'!K114 -> 22381.985 | P11: ='proyección hogares'!D31*'provincia (%)'!K114 -> 22724.946 | Q11: ='proyección hogares'!C31*'provincia (%)'!K114 -> 23052.329 | R11: ='proyección hogares'!B31*'provincia (%)'!K114 -> 23383.916
B12: Mujer | C12: ='proyección hogares'!Q31*'provincia (%)'!K115 -> 43077.289 | D12: ='proyección hogares'!P31*'provincia (%)'!K115 -> 44320.062 | E12: ='proyección hogares'!O31*'provincia (%)'!K115 -> 45510.366 | F12: ='proyección hogares'!N31*'provincia (%)'!K115 -> 46571.939 | G12: ='proyección hogares'!M31*'provincia (%)'!K115 -> 47693.301 | H12: ='proyección hogares'!L31*'provincia (%)'!K115 -> 48861.642 | I12: ='proyección hogares'!K31*'provincia (%)'!K115 -> 49910.403 | J12: ='proyección hogares'!J31*'provincia (%)'!K115 -> 50828.602 | K12: ='proyección hogares'!I31*'provincia (%)'!K115 -> 51715.077 | L12: ='proyección hogares'!H31*'provincia (%)'!K115 -> 52661.341 | M12: ='proyección hogares'!G31*'provincia (%)'!K115 -> 53556.967 | N12: ='proyección hogares'!F31*'provincia (%)'!K115 -> 54391.583 | O12: ='proyección hogares'!E31*'provincia (%)'!K115 -> 55224.369 | P12: ='proyección hogares'!D31*'provincia (%)'!K115 -> 56070.576 | Q12: ='proyección hogares'!C31*'provincia (%)'!K115 -> 56878.348 | R12: ='proyección hogares'!B31*'provincia (%)'!K115 -> 57696.491
A13: Almería | B13: Ambos Sexos | C13: ='proyección hogares'!Q38*'provincia (%)'!K21 -> 25392.219 | D13: ='proyección hogares'!P38*'provincia (%)'!K21 -> 26464.623 | E13: ='proyección hogares'!O38*'provincia (%)'!K21 -> 27542.754 | F13: ='proyección hogares'!N38*'provincia (%)'!K21 -> 28616.749 | G13: ='proyección hogares'!M38*'provincia (%)'!K21 -> 29663.385 | H13: ='proyección hogares'!L38*'provincia (%)'!K21 -> 30692.842 | I13: ='proyección hogares'!K38*'provincia (%)'!K21 -> 31649.13 | J13: ='proyección hogares'!J38*'provincia (%)'!K21 -> 32563.426 | K13: ='proyección hogares'!I38*'provincia (%)'!K21 -> 33449.09 | L13: ='proyección hogares'!H38*'provincia (%)'!K21 -> 34311.531 | M13: ='proyección hogares'!G38*'provincia (%)'!K21 -> 35147.567 | N13: ='proyección hogares'!F38*'provincia (%)'!K21 -> 35972.787 | O13: ='proyección hogares'!E38*'provincia (%)'!K21 -> 36801.188 | P13: ='proyección hogares'!D38*'provincia (%)'!K21 -> 37623.863 | Q13: ='proyección hogares'!C38*'provincia (%)'!K21 -> 38453.219 | R13: ='proyección hogares'!B38*'provincia (%)'!K21 -> 39270.168
B14: Hombre | C14: ='proyección hogares'!Q38*'provincia (%)'!K22 -> 14502.578 | D14: ='proyección hogares'!P38*'provincia (%)'!K22 -> 15115.074 | E14: ='proyección hogares'!O38*'provincia (%)'!K22 -> 15730.84 | F14: ='proyección hogares'!N38*'provincia (%)'!K22 -> 16344.244 | G14: ='proyección hogares'!M38*'provincia (%)'!K22 -> 16942.023 | H14: ='proyección hogares'!L38*'provincia (%)'!K22 -> 17529.99 | I14: ='proyección hogares'!K38*'provincia (%)'!K22 -> 18076.166 | J14: ='proyección hogares'!J38*'provincia (%)'!K22 -> 18598.36 | K14: ='proyección hogares'!I38*'provincia (%)'!K22 -> 19104.2 | L14: ='proyección hogares'!H38*'provincia (%)'!K22 -> 19596.777 | M14: ='proyección hogares'!G38*'provincia (%)'!K22 -> 20074.273 | N14: ='proyección hogares'!F38*'provincia (%)'!K22 -> 20545.591 | O14: ='proyección hogares'!E38*'provincia (%)'!K22 -> 21018.726 | P14: ='proyección hogares'!D38*'provincia (%)'!K22 -> 21488.591 | Q14: ='proyección hogares'!C38*'provincia (%)'!K22 -> 21962.272 | R14: ='proyección hogares'!B38*'provincia (%)'!K22 -> 22428.866
B15: Mujer | C15: ='proyección hogares'!Q38*'provincia (%)'!K23 -> 37653.795 | D15: ='proyección hogares'!P38*'provincia (%)'!K23 -> 39244.05 | E15: ='proyección hogares'!O38*'provincia (%)'!K23 -> 40842.796 | F15: ='proyección hogares'!N38*'provincia (%)'!K23 -> 42435.409 | G15: ='proyección hogares'!M38*'provincia (%)'!K23 -> 43987.452 | H15: ='proyección hogares'!L38*'provincia (%)'!K23 -> 45514.021 | I15: ='proyección hogares'!K38*'provincia (%)'!K23 -> 46932.089 | J15: ='proyección hogares'!J38*'provincia (%)'!K23 -> 48287.886 | K15: ='proyección hogares'!I38*'provincia (%)'!K23 -> 49601.226 | L15: ='proyección hogares'!H38*'provincia (%)'!K23 -> 50880.128 | M15: ='proyección hogares'!G38*'provincia (%)'!K23 -> 52119.876 | N15: ='proyección hogares'!F38*'provincia (%)'!K23 -> 53343.584 | O15: ='proyección hogares'!E38*'provincia (%)'!K23 -> 54572.01 | P15: ='proyección hogares'!D38*'provincia (%)'!K23 -> 55791.944 | Q15: ='proyección hogares'!C38*'provincia (%)'!K23 -> 57021.785 | R15: ='proyección hogares'!B38*'provincia (%)'!K23 -> 58233.228
A16: Huelva | B16: Ambos Sexos | C16: ='proyección hogares'!Q45*'provincia (%)'!K105 -> 16970.859 | D16: ='proyección hogares'!P45*'provincia (%)'!K105 -> 17565.214 | E16: ='proyección hogares'!O45*'provincia (%)'!K105 -> 18155.561 | F16: ='proyección hogares'!N45*'provincia (%)'!K105 -> 18721.554 | G16: ='proyección hogares'!M45*'provincia (%)'!K105 -> 19309.435 | H16: ='proyección hogares'!L45*'provincia (%)'!K105 -> 19888.993 | I16: ='proyección hogares'!K45*'provincia (%)'!K105 -> 20423.85 | J16: ='proyección hogares'!J45*'provincia (%)'!K105 -> 20927.88 | K16: ='proyección hogares'!I45*'provincia (%)'!K105 -> 21420.812 | L16: ='proyección hogares'!H45*'provincia (%)'!K105 -> 21899.564 | M16: ='proyección hogares'!G45*'provincia (%)'!K105 -> 22362.593 | N16: ='proyección hogares'!F45*'provincia (%)'!K105 -> 22819.457 | O16: ='proyección hogares'!E45*'provincia (%)'!K105 -> 23269.539 | P16: ='proyección hogares'!D45*'provincia (%)'!K105 -> 23710.064 | Q16: ='proyección hogares'!C45*'provincia (%)'!K105 -> 24148.74 | R16: ='proyección hogares'!B45*'provincia (%)'!K105 -> 24563.678
B17: Hombre | C17: ='proyección hogares'!Q45*'provincia (%)'!K106 -> 10474.23 | D17: ='proyección hogares'!P45*'provincia (%)'!K106 -> 10841.059 | E17: ='proyección hogares'!O45*'provincia (%)'!K106 -> 11205.415 | F17: ='proyección hogares'!N45*'provincia (%)'!K106 -> 11554.74 | G17: ='proyección hogares'!M45*'provincia (%)'!K106 -> 11917.574 | H17: ='proyección hogares'!L45*'provincia (%)'!K106 -> 12275.27 | I17: ='proyección hogares'!K45*'provincia (%)'!K106 -> 12605.379 | J17: ='proyección hogares'!J45*'provincia (%)'!K106 -> 12916.46 | K17: ='proyección hogares'!I45*'provincia (%)'!K106 -> 13220.693 | L17: ='proyección hogares'!H45*'provincia (%)'!K106 -> 13516.173 | M17: ='proyección hogares'!G45*'provincia (%)'!K106 -> 13801.95 | N17: ='proyección hogares'!F45*'provincia (%)'!K106 -> 14083.921 | O17: ='proyección hogares'!E45*'provincia (%)'!K106 -> 14361.707 | P17: ='proyección hogares'!D45*'provincia (%)'!K106 -> 14633.594 | Q17: ='proyección hogares'!C45*'provincia (%)'!K106 -> 14904.34 | R17: ='proyección hogares'!B45*'provincia (%)'!K106 -> 15160.435
B18: Mujer | C18: ='proyección hogares'!Q45*'provincia (%)'!K107 -> 22440.144 | D18: ='proyección hogares'!P45*'provincia (%)'!K107 -> 23226.044 | E18: ='proyección hogares'!O45*'provincia (%)'!K107 -> 24006.645 | F18: ='proyección hogares'!N45*'provincia (%)'!K107 -> 24755.044 | G18: ='proyección hogares'!M45*'provincia (%)'!K107 -> 25532.384 | H18: ='proyección hogares'!L45*'provincia (%)'!K107 -> 26298.718 | I18: ='proyección hogares'!K45*'provincia (%)'!K107 -> 27005.947 | J18: ='proyección hogares'!J45*'provincia (%)'!K107 -> 27672.413 | K18: ='proyección hogares'!I45*'provincia (%)'!K107 -> 28324.205 | L18: ='proyección hogares'!H45*'provincia (%)'!K107 -> 28957.246 | M18: ='proyección hogares'!G45*'provincia (%)'!K107 -> 29569.499 | N18: ='proyección hogares'!F45*'provincia (%)'!K107 -> 30173.598 | O18: ='proyección hogares'!E45*'provincia (%)'!K107 -> 30768.73 | P18: ='proyección hogares'!D45*'provincia (%)'!K107 -> 31351.226 | Q18: ='proyección hogares'!C45*'provincia (%)'!K107 -> 31931.276 | R18: ='proyección hogares'!B45*'provincia (%)'!K107 -> 32479.938
A19: Cádiz | B19: Ambos Sexos | C19: ='proyección hogares'!Q52*'provincia (%)'!K61 -> 40402.253 | D19: ='proyección hogares'!P52*'provincia (%)'!K61 -> 41948.916 | E19: ='proyección hogares'!O52*'provincia (%)'!K61 -> 43489.941 | F19: ='proyección hogares'!N52*'provincia (%)'!K61 -> 44995.484 | G19: ='proyección hogares'!M52*'provincia (%)'!K61 -> 46475.823 | H19: ='proyección hogares'!L52*'provincia (%)'!K61 -> 47954.504 | I19: ='proyección hogares'!K52*'provincia (%)'!K61 -> 49336.685 | J19: ='proyección hogares'!J52*'provincia (%)'!K61 -> 50649.557 | K19: ='proyección hogares'!I52*'provincia (%)'!K61 -> 51925.289 | L19: ='proyección hogares'!H52*'provincia (%)'!K61 -> 53188.419 | M19: ='proyección hogares'!G52*'provincia (%)'!K61 -> 54385.889 | N19: ='proyección hogares'!F52*'provincia (%)'!K61 -> 55550.86 | O19: ='proyección hogares'!E52*'provincia (%)'!K61 -> 56704.225 | P19: ='proyección hogares'!D52*'provincia (%)'!K61 -> 57825.754 | Q19: ='proyección hogares'!C52*'provincia (%)'!K61 -> 58940.651 | R19: ='proyección hogares'!B52*'provincia (%)'!K61 -> 59989.888
B20: Hombre | C20: ='proyección hogares'!Q52*'provincia (%)'!K62 -> 22974.821 | D20: ='proyección hogares'!P52*'provincia (%)'!K62 -> 23854.334 | E20: ='proyección hogares'!O52*'provincia (%)'!K62 -> 24730.641 | F20: ='proyección hogares'!N52*'provincia (%)'!K62 -> 25586.771 | G20: ='proyección hogares'!M52*'provincia (%)'!K62 -> 26428.568 | H20: ='proyección hogares'!L52*'provincia (%)'!K62 -> 27269.423 | I20: ='proyección hogares'!K52*'provincia (%)'!K62 -> 28055.403 | J20: ='proyección hogares'!J52*'provincia (%)'!K62 -> 28801.971 | K20: ='proyección hogares'!I52*'provincia (%)'!K62 -> 29527.418 | L20: ='proyección hogares'!H52*'provincia (%)'!K62 -> 30245.699 | M20: ='proyección hogares'!G52*'provincia (%)'!K62 -> 30926.643 | N20: ='proyección hogares'!F52*'provincia (%)'!K62 -> 31589.106 | O20: ='proyección hogares'!E52*'provincia (%)'!K62 -> 32244.969 | P20: ='proyección hogares'!D52*'provincia (%)'!K62 -> 32882.729 | Q20: ='proyección hogares'!C52*'provincia (%)'!K62 -> 33516.718 | R20: ='proyección hogares'!B52*'provincia (%)'!K62 -> 34113.368
B21: Mujer | C21: ='proyección hogares'!Q52*'provincia (%)'!K63 -> 56713.116 | D21: ='proyección hogares'!P52*'provincia (%)'!K63 -> 58884.184 | E21: ='proyección hogares'!O52*'provincia (%)'!K63 -> 61047.339 | F21: ='proyección hogares'!N52*'provincia (%)'!K63 -> 63160.687 | G21: ='proyección hogares'!M52*'provincia (%)'!K63 -> 65238.656 | H21: ='proyección hogares'!L52*'provincia (%)'!K63 -> 67314.298 | I21: ='proyección hogares'!K52*'provincia (%)'!K63 -> 69254.481 | J21: ='proyección hogares'!J52*'provincia (%)'!K63 -> 71097.376 | K21: ='proyección hogares'!I52*'provincia (%)'!K63 -> 72888.135 | L21: ='proyección hogares'!H52*'provincia (%)'!K63 -> 74661.206 | M21: ='proyección hogares'!G52*'provincia (%)'!K63 -> 76342.108 | N21: ='proyección hogares'!F52*'provincia (%)'!K63 -> 77977.392 | O21: ='proyección hogares'!E52*'provincia (%)'!K63 -> 79596.383 | P21: ='proyección hogares'!D52*'provincia (%)'!K63 -> 81170.688 | Q21: ='proyección hogares'!C52*'provincia (%)'!K63 -> 82735.682 | R21: ='proyección hogares'!B52*'provincia (%)'!K63 -> 84208.508
A22: Sevilla | B22: Ambos Sexos | C22: ='proyección hogares'!Q59*'provincia (%)'!K177 -> 64126.14 | D22: ='proyección hogares'!P59*'provincia (%)'!K177 -> 66490.612 | E22: ='proyección hogares'!O59*'provincia (%)'!K177 -> 68862.123 | F22: ='proyección hogares'!N59*'provincia (%)'!K177 -> 71124.189 | G22: ='proyección hogares'!M59*'provincia (%)'!K177 -> 73419.687 | H22: ='proyección hogares'!L59*'provincia (%)'!K177 -> 75728.206 | I22: ='proyección hogares'!K59*'provincia (%)'!K177 -> 77901.943 | J22: ='proyección hogares'!J59*'provincia (%)'!K177 -> 79946.882 | K22: ='proyección hogares'!I59*'provincia (%)'!K177 -> 81997.452 | L22: ='proyección hogares'!H59*'provincia (%)'!K177 -> 84015.646 | M22: ='proyección hogares'!G59*'provincia (%)'!K177 -> 85955.365 | N22: ='proyección hogares'!F59*'provincia (%)'!K177 -> 87862.004 | O22: ='proyección hogares'!E59*'provincia (%)'!K177 -> 89747.529 | P22: ='proyección hogares'!D59*'provincia (%)'!K177 -> 91584.138 | Q22: ='proyección hogares'!C59*'provincia (%)'!K177 -> 93413.358 | R22: ='proyección hogares'!B59*'provincia (%)'!K177 -> 95166.213
B23: Hombre | C23: ='proyección hogares'!Q59*'provincia (%)'!K178 -> 32843.12 | D23: ='proyección hogares'!P59*'provincia (%)'!K178 -> 34054.118 | E23: ='proyección hogares'!O59*'provincia (%)'!K178 -> 35268.721 | F23: ='proyección hogares'!N59*'provincia (%)'!K178 -> 36427.271 | G23: ='proyección hogares'!M59*'provincia (%)'!K178 -> 37602.943 | H23: ='proyección hogares'!L59*'provincia (%)'!K178 -> 38785.284 | I23: ='proyección hogares'!K59*'provincia (%)'!K178 -> 39898.595 | J23: ='proyección hogares'!J59*'provincia (%)'!K178 -> 40945.939 | K23: ='proyección hogares'!I59*'provincia (%)'!K178 -> 41996.168 | L23: ='proyección hogares'!H59*'provincia (%)'!K178 -> 43029.815 | M23: ='proyección hogares'!G59*'provincia (%)'!K178 -> 44023.27 | N23: ='proyección hogares'!F59*'provincia (%)'!K178 -> 44999.782 | O23: ='proyección hogares'!E59*'provincia (%)'!K178 -> 45965.481 | P23: ='proyección hogares'!D59*'provincia (%)'!K178 -> 46906.127 | Q23: ='proyección hogares'!C59*'provincia (%)'!K178 -> 47842.987 | R23: ='proyección hogares'!B59*'provincia (%)'!K178 -> 48740.737
B24: Mujer | C24: ='proyección hogares'!Q59*'provincia (%)'!K179 -> 89697.985 | D24: ='proyección hogares'!P59*'provincia (%)'!K179 -> 93005.347 | E24: ='proyección hogares'!O59*'provincia (%)'!K179 -> 96322.554 | F24: ='proyección hogares'!N59*'provincia (%)'!K179 -> 99486.674 | G24: ='proyección hogares'!M59*'provincia (%)'!K179 -> 102697.56 | H24: ='proyección hogares'!L59*'provincia (%)'!K179 -> 105926.65 | I24: ='proyección hogares'!K59*'provincia (%)'!K179 -> 108967.22 | J24: ='proyección hogares'!J59*'provincia (%)'!K179 -> 111827.63 | K24: ='proyección hogares'!I59*'provincia (%)'!K179 -> 114695.91 | L24: ='proyección hogares'!H59*'provincia (%)'!K179 -> 117518.91 | M24: ='proyección hogares'!G59*'provincia (%)'!K179 -> 120232.14 | N24: ='proyección hogares'!F59*'provincia (%)'!K179 -> 122899.1 | O24: ='proyección hogares'!E59*'provincia (%)'!K179 -> 125536.52 | P24: ='proyección hogares'!D59*'provincia (%)'!K179 -> 128105.52 | Q24: ='proyección hogares'!C59*'provincia (%)'!K179 -> 130664.19 | R24: ='proyección hogares'!B59*'provincia (%)'!K179 -> 133116.04
A25: Granada | B25: Ambos Sexos | C25: ='proyección hogares'!Q66*'provincia (%)'!K97 -> 38474.052 | D25: ='proyección hogares'!P66*'provincia (%)'!K97 -> 39857.118 | E25: ='proyección hogares'!O66*'provincia (%)'!K97 -> 41251.346 | F25: ='proyección hogares'!N66*'provincia (%)'!K97 -> 42609.791 | G25: ='proyección hogares'!M66*'provincia (%)'!K97 -> 43956.417 | H25: ='proyección hogares'!L66*'provincia (%)'!K97 -> 45281.376 | I25: ='proyección hogares'!K66*'provincia (%)'!K97 -> 46503.254 | J25: ='proyección hogares'!J66*'provincia (%)'!K97 -> 47657.177 | K25: ='proyección hogares'!I66*'provincia (%)'!K97 -> 48788.776 | L25: ='proyección hogares'!H66*'provincia (%)'!K97 -> 49881.31 | M25: ='proyección hogares'!G66*'provincia (%)'!K97 -> 50927.555 | N25: ='proyección hogares'!F66*'provincia (%)'!K97 -> 51963.295 | O25: ='proyección hogares'!E66*'provincia (%)'!K97 -> 52979.667 | P25: ='proyección hogares'!D66*'provincia (%)'!K97 -> 53989.144 | Q25: ='proyección hogares'!C66*'provincia (%)'!K97 -> 54963.166 | R25: ='proyección hogares'!B66*'provincia (%)'!K97 -> 55910.269
B26: Hombre | C26: ='proyección hogares'!Q66*'provincia (%)'!K98 -> 17984.81 | D26: ='proyección hogares'!P66*'provincia (%)'!K98 -> 18631.328 | E26: ='proyección hogares'!O66*'provincia (%)'!K98 -> 19283.064 | F26: ='proyección hogares'!N66*'provincia (%)'!K98 -> 19918.073 | G26: ='proyección hogares'!M66*'provincia (%)'!K98 -> 20547.557 | H26: ='proyección hogares'!L66*'provincia (%)'!K98 -> 21166.914 | I26: ='proyección hogares'!K66*'provincia (%)'!K98 -> 21738.084 | J26: ='proyección hogares'!J66*'provincia (%)'!K98 -> 22277.489 | K26: ='proyección hogares'!I66*'provincia (%)'!K98 -> 22806.458 | L26: ='proyección hogares'!H66*'provincia (%)'!K98 -> 23317.166 | M26: ='proyección hogares'!G66*'provincia (%)'!K98 -> 23806.237 | N26: ='proyección hogares'!F66*'provincia (%)'!K98 -> 24290.396 | O26: ='proyección hogares'!E66*'provincia (%)'!K98 -> 24765.502 | P26: ='proyección hogares'!D66*'provincia (%)'!K98 -> 25237.385 | Q26: ='proyección hogares'!C66*'provincia (%)'!K98 -> 25692.695 | R26: ='proyección hogares'!B66*'provincia (%)'!K98 -> 26135.421
B27: Mujer | C27: ='proyección hogares'!Q66*'provincia (%)'!K99 -> 58197.986 | D27: ='proyección hogares'!P66*'provincia (%)'!K99 -> 60290.088 | E27: ='proyección hogares'!O66*'provincia (%)'!K99 -> 62399.074 | F27: ='proyección hogares'!N66*'provincia (%)'!K99 -> 64453.933 | G27: ='proyección hogares'!M66*'provincia (%)'!K99 -> 66490.914 | H27: ='proyección hogares'!L66*'provincia (%)'!K99 -> 68495.121 | I27: ='proyección hogares'!K66*'provincia (%)'!K99 -> 70343.402 | J27: ='proyección hogares'!J66*'provincia (%)'!K99 -> 72088.889 | K27: ='proyección hogares'!I66*'provincia (%)'!K99 -> 73800.609 | L27: ='proyección hogares'!H66*'provincia (%)'!K99 -> 75453.236 | M27: ='proyección hogares'!G66*'provincia (%)'!K99 -> 77035.845 | N27: ='proyección hogares'!F66*'provincia (%)'!K99 -> 78602.563 | O27: ='proyección hogares'!E66*'provincia (%)'!K99 -> 80139.982 | P27: ='proyección hogares'!D66*'provincia (%)'!K99 -> 81666.974 | Q27: ='proyección hogares'!C66*'provincia (%)'!K99 -> 83140.334 | R27: ='proyección hogares'!B66*'provincia (%)'!K99 -> 84572.975
A28: Córdoba | B28: Ambos Sexos | C28: ='proyección hogares'!Q73*'provincia (%)'!K77 -> 32066.238 | D28: ='proyección hogares'!P73*'provincia (%)'!K77 -> 33144.036 | E28: ='proyección hogares'!O73*'provincia (%)'!K77 -> 34186.866 | F28: ='proyección hogares'!N73*'provincia (%)'!K77 -> 35160.536 | G28: ='proyección hogares'!M73*'provincia (%)'!K77 -> 36160.238 | H28: ='proyección hogares'!L73*'provincia (%)'!K77 -> 37159.164 | I28: ='proyección hogares'!K73*'provincia (%)'!K77 -> 38078.051 | J28: ='proyección hogares'!J73*'provincia (%)'!K77 -> 38899.026 | K28: ='proyección hogares'!I73*'provincia (%)'!K77 -> 39728.55 | L28: ='proyección hogares'!H73*'provincia (%)'!K77 -> 40559.628 | M28: ='proyección hogares'!G73*'provincia (%)'!K77 -> 41350.298 | N28: ='proyección hogares'!F73*'provincia (%)'!K77 -> 42118.822 | O28: ='proyección hogares'!E73*'provincia (%)'!K77 -> 42866.753 | P28: ='proyección hogares'!D73*'provincia (%)'!K77 -> 43608.856 | Q28: ='proyección hogares'!C73*'provincia (%)'!K77 -> 44332.309 | R28: ='proyección hogares'!B73*'provincia (%)'!K77 -> 45028.954
B29: Hombre | C29: ='proyección hogares'!Q73*'provincia (%)'!K78 -> 16284.48 | D29: ='proyección hogares'!P73*'provincia (%)'!K78 -> 16831.828 | E29: ='proyección hogares'!O73*'provincia (%)'!K78 -> 17361.417 | F29: ='proyección hogares'!N73*'provincia (%)'!K78 -> 17855.885 | G29: ='proyección hogares'!M73*'provincia (%)'!K78 -> 18363.573 | H29: ='proyección hogares'!L73*'provincia (%)'!K78 -> 18870.866 | I29: ='proyección hogares'!K73*'provincia (%)'!K78 -> 19337.512 | J29: ='proyección hogares'!J73*'provincia (%)'!K78 -> 19754.435 | K29: ='proyección hogares'!I73*'provincia (%)'!K78 -> 20175.7 | L29: ='proyección hogares'!H73*'provincia (%)'!K78 -> 20597.753 | M29: ='proyección hogares'!G73*'provincia (%)'!K78 -> 20999.286 | N29: ='proyección hogares'!F73*'provincia (%)'!K78 -> 21389.572 | O29: ='proyección hogares'!E73*'provincia (%)'!K78 -> 21769.401 | P29: ='proyección hogares'!D73*'provincia (%)'!K78 -> 22146.27 | Q29: ='proyección hogares'!C73*'provincia (%)'!K78 -> 22513.667 | R29: ='proyección hogares'!B73*'provincia (%)'!K78 -> 22867.45
B30: Mujer | C30: ='proyección hogares'!Q73*'provincia (%)'!K79 -> 46248.796 | D30: ='proyección hogares'!P73*'provincia (%)'!K79 -> 47803.292 | E30: ='proyección hogares'!O73*'provincia (%)'!K79 -> 49307.355 | F30: ='proyección hogares'!N73*'provincia (%)'!K79 -> 50711.669 | G30: ='proyección hogares'!M73*'provincia (%)'!K79 -> 52153.529 | H30: ='proyección hogares'!L73*'provincia (%)'!K79 -> 53594.269 | I30: ='proyección hogares'!K73*'provincia (%)'!K79 -> 54919.569 | J30: ='proyección hogares'!J73*'provincia (%)'!K79 -> 56103.654 | K30: ='proyección hogares'!I73*'provincia (%)'!K79 -> 57300.068 | L30: ='proyección hogares'!H73*'provincia (%)'!K79 -> 58498.722 | M30: ='proyección hogares'!G73*'provincia (%)'!K79 -> 59639.097 | N30: ='proyección hogares'!F73*'provincia (%)'!K79 -> 60747.531 | O30: ='proyección hogares'!E73*'provincia (%)'!K79 -> 61826.264 | P30: ='proyección hogares'!D73*'provincia (%)'!K79 -> 62896.592 | Q30: ='proyección hogares'!C73*'provincia (%)'!K79 -> 63940.021 | R30: ='proyección hogares'!B73*'provincia (%)'!K79 -> 64944.784
A31: Zaragoza | B31: Ambos Sexos | C31: ='proyección hogares'!Q87*'provincia (%)'!K209 -> 47697.022 | D31: ='proyección hogares'!P87*'provincia (%)'!K209 -> 49266.227 | E31: ='proyección hogares'!O87*'provincia (%)'!K209 -> 50858.627 | F31: ='proyección hogares'!N87*'provincia (%)'!K209 -> 52444.456 | G31: ='proyección hogares'!M87*'provincia (%)'!K209 -> 54026.032 | H31: ='proyección hogares'!L87*'provincia (%)'!K209 -> 55616.5 | I31: ='proyección hogares'!K87*'provincia (%)'!K209 -> 57116.89 | J31: ='proyección hogares'!J87*'provincia (%)'!K209 -> 58576.301 | K31: ='proyección hogares'!I87*'provincia (%)'!K209 -> 60001.691 | L31: ='proyección hogares'!H87*'provincia (%)'!K209 -> 61426.307 | M31: ='proyección hogares'!G87*'provincia (%)'!K209 -> 62783.27 | N31: ='proyección hogares'!F87*'provincia (%)'!K209 -> 64127.474 | O31: ='proyección hogares'!E87*'provincia (%)'!K209 -> 65475.157 | P31: ='proyección hogares'!D87*'provincia (%)'!K209 -> 66795.779 | Q31: ='proyección hogares'!C87*'provincia (%)'!K209 -> 68100.164 | R31: ='proyección hogares'!B87*'provincia (%)'!K209 -> 69347.718
B32: Hombre | C32: ='proyección hogares'!Q87*'provincia (%)'!K210 -> 30384.412 | D32: ='proyección hogares'!P87*'provincia (%)'!K210 -> 31384.041 | E32: ='proyección hogares'!O87*'provincia (%)'!K210 -> 32398.448 | F32: ='proyección hogares'!N87*'provincia (%)'!K210 -> 33408.667 | G32: ='proyección hogares'!M87*'provincia (%)'!K210 -> 34416.178 | H32: ='proyección hogares'!L87*'provincia (%)'!K210 -> 35429.353 | I32: ='proyección hogares'!K87*'provincia (%)'!K210 -> 36385.146 | J32: ='proyección hogares'!J87*'provincia (%)'!K210 -> 37314.834 | K32: ='proyección hogares'!I87*'provincia (%)'!K210 -> 38222.849 | L32: ='proyección hogares'!H87*'provincia (%)'!K210 -> 39130.372 | M32: ='proyección hogares'!G87*'provincia (%)'!K210 -> 39994.797 | N32: ='proyección hogares'!F87*'provincia (%)'!K210 -> 40851.095 | O32: ='proyección hogares'!E87*'provincia (%)'!K210 -> 41709.609 | P32: ='proyección hogares'!D87*'provincia (%)'!K210 -> 42550.884 | Q32: ='proyección hogares'!C87*'provincia (%)'!K210 -> 43381.816 | R32: ='proyección hogares'!B87*'provincia (%)'!K210 -> 44176.545
B33: Mujer | C33: ='proyección hogares'!Q87*'provincia (%)'!K211 -> 60260.806 | D33: ='proyección hogares'!P87*'provincia (%)'!K211 -> 62243.352 | E33: ='proyección hogares'!O87*'provincia (%)'!K211 -> 64255.204 | F33: ='proyección hogares'!N87*'provincia (%)'!K211 -> 66258.753 | G33: ='proyección hogares'!M87*'provincia (%)'!K211 -> 68256.929 | H33: ='proyección hogares'!L87*'provincia (%)'!K211 -> 70266.338 | I33: ='proyección hogares'!K87*'provincia (%)'!K211 -> 72161.944 | J33: ='proyección hogares'!J87*'provincia (%)'!K211 -> 74005.775 | K33: ='proyección hogares'!I87*'provincia (%)'!K211 -> 75806.624 | L33: ='proyección hogares'!H87*'provincia (%)'!K211 -> 77606.497 | M33: ='proyección hogares'!G87*'provincia (%)'!K211 -> 79320.894 | N33: ='proyección hogares'!F87*'provincia (%)'!K211 -> 81019.172 | O33: ='proyección hogares'!E87*'provincia (%)'!K211 -> 82721.847 | P33: ='proyección hogares'!D87*'provincia (%)'!K211 -> 84390.331 | Q33: ='proyección hogares'!C87*'provincia (%)'!K211 -> 86038.301 | R33: ='proyección hogares'!B87*'provincia (%)'!K211 -> 87614.472
A34: Teruel | B34: Ambos Sexos | C34: ='proyección hogares'!Q94*'provincia (%)'!K189 -> 7456.6152 | D34: ='proyección hogares'!P94*'provincia (%)'!K189 -> 7689.7736 | E34: ='proyección hogares'!O94*'provincia (%)'!K189 -> 7916.8601 | F34: ='proyección hogares'!N94*'provincia (%)'!K189 -> 8138.2796 | G34: ='proyección hogares'!M94*'provincia (%)'!K189 -> 8367.7949 | H34: ='proyección hogares'!L94*'provincia (%)'!K189 -> 8590.0239 | I34: ='proyección hogares'!K94*'provincia (%)'!K189 -> 8804.562 | J34: ='proyección hogares'!J94*'provincia (%)'!K189 -> 9014.2426 | K34: ='proyección hogares'!I94*'provincia (%)'!K189 -> 9216.2323 | L34: ='proyección hogares'!H94*'provincia (%)'!K189 -> 9418.6267 | M34: ='proyección hogares'!G94*'provincia (%)'!K189 -> 9620.2115 | N34: ='proyección hogares'!F94*'provincia (%)'!K189 -> 9805.2 | O34: ='proyección hogares'!E94*'provincia (%)'!K189 -> 9996.2604 | P34: ='proyección hogares'!D94*'provincia (%)'!K189 -> 10181.654 | Q34: ='proyección hogares'!C94*'provincia (%)'!K189 -> 10371.5 | R34: ='proyección hogares'!B94*'provincia (%)'!K189 -> 10548.392
B35: Hombre | C35: ='proyección hogares'!Q94*'provincia (%)'!K190 -> 4996.4153 | D35: ='proyección hogares'!P94*'provincia (%)'!K190 -> 5152.6466 | E35: ='proyección hogares'!O94*'provincia (%)'!K190 -> 5304.8093 | F35: ='proyección hogares'!N94*'provincia (%)'!K190 -> 5453.1747 | G35: ='proyección hogares'!M94*'provincia (%)'!K190 -> 5606.9648 | H35: ='proyección hogares'!L94*'provincia (%)'!K190 -> 5755.8726 | I35: ='proyección hogares'!K94*'provincia (%)'!K190 -> 5899.6271 | J35: ='proyección hogares'!J94*'provincia (%)'!K190 -> 6040.1267 | K35: ='proyección hogares'!I94*'provincia (%)'!K190 -> 6175.4728 | L35: ='proyección hogares'!H94*'provincia (%)'!K190 -> 6311.0902 | M35: ='proyección hogares'!G94*'provincia (%)'!K190 -> 6446.1651 | N35: ='proyección hogares'!F94*'provincia (%)'!K190 -> 6570.1194 | O35: ='proyección hogares'!E94*'provincia (%)'!K190 -> 6698.1422 | P35: ='proyección hogares'!D94*'provincia (%)'!K190 -> 6822.3677 | Q35: ='proyección hogares'!C94*'provincia (%)'!K190 -> 6949.5768 | R35: ='proyección hogares'!B94*'provincia (%)'!K190 -> 7068.1064
B36: Mujer | C36: ='proyección hogares'!Q94*'provincia (%)'!K191 -> 10475.799 | D36: ='proyección hogares'!P94*'provincia (%)'!K191 -> 10803.363 | E36: ='proyección hogares'!O94*'provincia (%)'!K191 -> 11122.397 | F36: ='proyección hogares'!N94*'provincia (%)'!K191 -> 11433.469 | G36: ='proyección hogares'!M94*'provincia (%)'!K191 -> 11755.915 | H36: ='proyección hogares'!L94*'provincia (%)'!K191 -> 12068.125 | I36: ='proyección hogares'!K94*'provincia (%)'!K191 -> 12369.53 | J36: ='proyección hogares'!J94*'provincia (%)'!K191 -> 12664.11 | K36: ='proyección hogares'!I94*'provincia (%)'!K191 -> 12947.885 | L36: ='proyección hogares'!H94*'provincia (%)'!K191 -> 13232.229 | M36: ='proyección hogares'!G94*'provincia (%)'!K191 -> 13515.436 | N36: ='proyección hogares'!F94*'provincia (%)'!K191 -> 13775.326 | O36: ='proyección hogares'!E94*'provincia (%)'!K191 -> 14043.747 | P36: ='proyección hogares'!D94*'provincia (%)'!K191 -> 14304.206 | Q36: ='proyección hogares'!C94*'provincia (%)'!K191 -> 14570.92 | R36: ='proyección hogares'!B94*'provincia (%)'!K191 -> 14819.437
A37: Huesca | B37: Ambos Sexos | C37: ='proyección hogares'!Q101*'provincia (%)'!K109 -> 10775.051 | D37: ='proyección hogares'!P101*'provincia (%)'!K109 -> 11131.402 | E37: ='proyección hogares'!O101*'provincia (%)'!K109 -> 11489.939 | F37: ='proyección hogares'!N101*'provincia (%)'!K109 -> 11840.459 | G37: ='proyección hogares'!M101*'provincia (%)'!K109 -> 12184.786 | H37: ='proyección hogares'!L101*'provincia (%)'!K109 -> 12538.222 | I37: ='proyección hogares'!K101*'provincia (%)'!K109 -> 12875.989 | J37: ='proyección hogares'!J101*'provincia (%)'!K109 -> 13195.539 | K37: ='proyección hogares'!I101*'provincia (%)'!K109 -> 13511.445 | L37: ='proyección hogares'!H101*'provincia (%)'!K109 -> 13826.987 | M37: ='proyección hogares'!G101*'provincia (%)'!K109 -> 14135.605 | N37: ='proyección hogares'!F101*'provincia (%)'!K109 -> 14433.293 | O37: ='proyección hogares'!E101*'provincia (%)'!K109 -> 14736.81 | P37: ='proyección hogares'!D101*'provincia (%)'!K109 -> 15030.49 | Q37: ='proyección hogares'!C101*'provincia (%)'!K109 -> 15324.169 | R37: ='proyección hogares'!B101*'provincia (%)'!K109 -> 15604.003
B38: Hombre | C38: ='proyección hogares'!Q101*'provincia (%)'!K110 -> 6391.8203 | D38: ='proyección hogares'!P101*'provincia (%)'!K110 -> 6603.2095 | E38: ='proyección hogares'!O101*'provincia (%)'!K110 -> 6815.8955 | F38: ='proyección hogares'!N101*'provincia (%)'!K110 -> 7023.8263 | G38: ='proyección hogares'!M101*'provincia (%)'!K110 -> 7228.0827 | H38: ='proyección hogares'!L101*'provincia (%)'!K110 -> 7437.7427 | I38: ='proyección hogares'!K101*'provincia (%)'!K110 -> 7638.1085 | J38: ='proyección hogares'!J101*'provincia (%)'!K110 -> 7827.6671 | K38: ='proyección hogares'!I101*'provincia (%)'!K110 -> 8015.0643 | L38: ='proyección hogares'!H101*'provincia (%)'!K110 -> 8202.2453 | M38: ='proyección hogares'!G101*'provincia (%)'!K110 -> 8385.3195 | N38: ='proyección hogares'!F101*'provincia (%)'!K110 -> 8561.9094 | O38: ='proyección hogares'!E101*'provincia (%)'!K110 -> 8741.9577 | P38: ='proyección hogares'!D101*'provincia (%)'!K110 -> 8916.17 | Q38: ='proyección hogares'!C101*'provincia (%)'!K110 -> 9090.3823 | R38: ='proyección hogares'!B101*'provincia (%)'!K110 -> 9256.3812
B39: Mujer | C39: ='proyección hogares'!Q101*'provincia (%)'!K111 -> 16201.023 | D39: ='proyección hogares'!P101*'provincia (%)'!K111 -> 16736.82 | E39: ='proyección hogares'!O101*'provincia (%)'!K111 -> 17275.905 | F39: ='proyección hogares'!N101*'provincia (%)'!K111 -> 17802.936 | G39: ='proyección hogares'!M101*'provincia (%)'!K111 -> 18320.655 | H39: ='proyección hogares'!L101*'provincia (%)'!K111 -> 18852.069 | I39: ='proyección hogares'!K101*'provincia (%)'!K111 -> 19359.926 | J39: ='proyección hogares'!J101*'provincia (%)'!K111 -> 19840.391 | K39: ='proyección hogares'!I101*'provincia (%)'!K111 -> 20315.377 | L39: ='proyección hogares'!H101*'provincia (%)'!K111 -> 20789.815 | M39: ='proyección hogares'!G101*'provincia (%)'!K111 -> 21253.844 | N39: ='proyección hogares'!F101*'provincia (%)'!K111 -> 21701.438 | O39: ='proyección hogares'!E101*'provincia (%)'!K111 -> 22157.797 | P39: ='proyección hogares'!D101*'provincia (%)'!K111 -> 22599.364 | Q39: ='proyección hogares'!C101*'provincia (%)'!K111 -> 23040.931 | R39: ='proyección hogares'!B101*'provincia (%)'!K111 -> 23461.68
A40: Asturias | B40: Ambos Sexos | C40: ='proyección hogares'!Q115*'provincia (%)'!K29 -> 59854.576 | D40: ='proyección hogares'!P115*'provincia (%)'!K29 -> 61035.45 | E40: ='proyección hogares'!O115*'provincia (%)'!K29 -> 62230.332 | F40: ='proyección hogares'!N115*'provincia (%)'!K29 -> 63401.479 | G40: ='proyección hogares'!M115*'provincia (%)'!K29 -> 64545.001 | H40: ='proyección hogares'!L115*'provincia (%)'!K29 -> 65676.851 | I40: ='proyección hogares'!K115*'provincia (%)'!K29 -> 66760.065 | J40: ='proyección hogares'!J115*'provincia (%)'!K29 -> 67766.24 | K40: ='proyección hogares'!I115*'provincia (%)'!K29 -> 68753.35 | L40: ='proyección hogares'!H115*'provincia (%)'!K29 -> 69737.347 | M40: ='proyección hogares'!G115*'provincia (%)'!K29 -> 70638.469 | N40: ='proyección hogares'!F115*'provincia (%)'!K29 -> 71517.413 | O40: ='proyección hogares'!E115*'provincia (%)'!K29 -> 72380.405 | P40: ='proyección hogares'!D115*'provincia (%)'!K29 -> 73217.328 | Q40: ='proyección hogares'!C115*'provincia (%)'!K29 -> 74013.397 | R40: ='proyección hogares'!B115*'provincia (%)'!K29 -> 74739.041
...

Sheet proyección hogares unipersona.
A1: Proyección de Hogares Unipersonales por Territorio y Año
A2: Serie 2024–2039 · Hogares de personas residentes en viviendas familiares en España a 1 de enero
A3: Territorio | B3: 2024 | C3: 2025 | D3: 2026 | E3: 2027 | F3: 2028 | G3: 2029 | H3: 2030 | I3: 2031 | J3: 2032 | K3: 2033 | L3: 2034 | M3: 2035 | N3: 2036 | O3: 2037 | P3: 2038 | Q3: 2039
A4: Total Nacional | B4: 5433969 | C4: 5611451 | D4: 5789248 | E4: 5961960 | F4: 6132953 | G4: 6303421 | H4: 6463401 | I4: 6615200 | J4: 6762485 | K4: 6907696 | L4: 7046473 | M4: 7183233 | N4: 7318562 | O4: 7451795 | P4: 7582691 | Q4: 7708869
A5: Andalucía | B5: 903822 | C5: 937903 | D5: 971878 | E5: 1004529 | F5: 1037113 | G5: 1069331 | H5: 1099254 | I5: 1127239 | J5: 1154689 | K5: 1181731 | L5: 1207555 | M5: 1232803 | N5: 1257728 | O5: 1282246 | P5: 1306426 | Q5: 1329776
A6: Málaga | B6: 194560 | C6: 202935 | D6: 211338 | E6: 219425 | F6: 227312 | G6: 234873 | H6: 241904 | I6: 248477 | J6: 254835 | K6: 261051 | L6: 266932 | M6: 272672 | N6: 278311 | O6: 283841 | P6: 289278 | Q6: 294550
A7: Jaén | B7: 70607 | C7: 72644 | D7: 74595 | E7: 76335 | F7: 78173 | G7: 80088 | H7: 81807 | I7: 83312 | J7: 84765 | K7: 86316 | L7: 87784 | M7: 89152 | N7: 90517 | O7: 91904 | P7: 93228 | Q7: 94569
A8: Almería | B8: 79818 | C8: 83189 | D8: 86578 | E8: 89954 | F8: 93244 | G8: 96480 | H8: 99486 | I8: 102360 | J8: 105144 | K8: 107855 | L8: 110483 | M8: 113077 | N8: 115681 | O8: 118267 | P8: 120874 | Q8: 123442
A9: Huelva | B9: 55051 | C9: 56979 | D9: 58894 | E9: 60730 | F9: 62637 | G9: 64517 | H9: 66252 | I9: 67887 | J9: 69486 | K9: 71039 | L9: 72541 | M9: 74023 | N9: 75483 | O9: 76912 | P9: 78335 | Q9: 79681
A10: Cádiz | B10: 121834 | C10: 126498 | D10: 131145 | E10: 135685 | F10: 140149 | G10: 144608 | H10: 148776 | I10: 152735 | J10: 156582 | K10: 160391 | L10: 164002 | M10: 167515 | N10: 170993 | O10: 174375 | P10: 177737 | Q10: 180901
A11: Sevilla | B11: 182224 | C11: 188943 | D11: 195682 | E11: 202110 | F11: 208633 | G11: 215193 | H11: 221370 | I11: 227181 | J11: 233008 | K11: 238743 | L11: 244255 | M11: 249673 | N11: 255031 | O11: 260250 | P11: 265448 | Q11: 270429
A12: Granada | B12: 117197 | C12: 121410 | D12: 125657 | E12: 129795 | F12: 133897 | G12: 137933 | H12: 141655 | I12: 145170 | J12: 148617 | K12: 151945 | L12: 155132 | M12: 158287 | N12: 161383 | O12: 164458 | P12: 167425 | Q12: 170310
A13: Córdoba | B13: 82531 | C13: 85305 | D13: 87989 | E13: 90495 | F13: 93068 | G13: 95639 | H13: 98004 | I13: 100117 | J13: 102252 | K13: 104391 | L13: 106426 | M13: 108404 | N13: 110329 | O13: 112239 | P13: 114101 | Q13: 115894
A14: Aragón | B14: 171369 | C14: 176982 | D14: 182646 | E14: 188257 | F14: 193860 | G14: 199493 | H14: 204831 | I14: 210001 | J14: 215054 | K14: 220105 | L14: 224960 | M14: 229711 | N14: 234502 | O14: 239182 | P14: 243831 | Q14: 248263
A15: Zaragoza | B15: 123376 | C15: 127435 | D15: 131554 | E15: 135656 | F15: 139747 | G15: 143861 | H15: 147742 | I15: 151517 | J15: 155204 | K15: 158889 | L15: 162399 | M15: 165876 | N15: 169362 | O15: 172778 | P15: 176152 | Q15: 179379
... A75: Melilla | B75: 5188 | C75: 5439 | D75: 5683 | E75: 5924 | F75: 6161 | G75: 6390 | H75: 6617 | I75: 6847 | J75: 7070 | K75: 7288 | L75: 7496 | M75: 7705 | N75: 7905 | O75: 8101 | P75: 8297 | Q75: 8485
A77: Fuente: INE – Proyecciones de Hogares 2024–2039

Sheet provincia (%)
A1: Año 2021
A2: Datos provinciales
A4: Hogares de una sola persona (unipersonales) según sexo y edad.
A5: Unidades: Hogares
B7: Menos de 30 años | C7: De 30 a 39 años | D7: De 40 a 49 años | E7: De 50 a 59 años | F7: De 60 a 69 años | G7: De 70 a 79 años | H7: De 80 y más años | I7: Total | K7: PORCENTAJE DE MAYORES DE 70
A8: Total Nacional
A9: Ambos Sexos | B9: 215287 | C9: 634371 | D9: 827023 | E9: 757655 | F9: 836056 | G9: 856096 | H9: 855206 | I9: 4981696 | K9: =((G9+H9)/I9) -> 0.34351795
A10: Hombre | B10: 125071 | C10: 371935 | D10: 527786 | E10: 466676 | F10: 364671 | G10: 251839 | H10: 204547 | I10: 2312523 | K10: =((G10+H10)/I10) -> 0.19735415
A11: Mujer | B11: 90217 | C11: 262437 | D11: 299237 | E11: 290979 | F11: 471386 | G11: 604258 | H11: 650659 | I11: 2669173 | K11: =((G11+H11)/I11) -> 0.47015199
A12: Albacete
A13: Ambos Sexos | B13: 2438 | C13: 5629 | D13: 5838 | E13: 4684 | F13: 5326 | G13: 7588 | H13: 8467 | I13: 39969 | K13: =((G13+H13)/I13) -> 0.40168631
A14: Hombre | B14: 1453 | C14: 3880 | D14: 4213 | E14: 3046 | F14: 2348 | G14: 2137 | H14: 2988 | I14: 20066 | K14: =((G14+H14)/I14) -> 0.25540716
A15: Mujer | B15: 984 | C15: 1748 | D15: 1625 | E15: 1638 | F15: 2978 | G15: 5451 | H15: 5479 | I15: 19903 | K15: =((G15+H15)/I15) -> 0.54916344
A16: Alicante/Alacant
A17: Ambos Sexos | B17: 9340 | C17: 20068 | D17: 30014 | E17: 33345 | F17: 39127 | G17: 39634 | H17: 34786 | I17: 206314 | K17: =((G17+H17)/I17) -> 0.36071231
A18: Hombre | B18: 5590 | C18: 10223 | D18: 19957 | E18: 18877 | F18: 17410 | G18: 15080 | H18: 8075 | I18: 95212 | K18: =((G18+H18)/I18) -> 0.24319414
A19: Mujer | B19: 3750 | C19: 9846 | D19: 10057 | E19: 14468 | F19: 21717 | G19: 24554 | H19: 26711 | I19: 111102 | K19: =((G19+H19)/I19) -> 0.46142284
A20: Almería
A21: Ambos Sexos | B21: 3214 | C21: 11249 | D21: 8515 | E21: 8170 | F21: 10853 | G21: 11916 | H21: 7679 | I21: 61595 | K21: =((G21+H21)/I21) -> 0.31812647
A22: Hombre | B22: 1932 | C22: 8362 | D22: 5932 | E22: 5510 | F22: 4961 | G22: 3940 | H22: 1988 | I22: 32626 | K22: =((G22+H22)/I22) -> 0.18169558
A23: Mujer | B23: 1282 | C23: 2887 | D23: 2582 | E23: 2660 | F23: 5892 | G23: 7975 | H23: 5691 | I23: 28969 | K23: =((G23+H23)/I23) -> 0.47174566
A24: Araba/Álava
A25: Ambos Sexos | B25: 2190 | C25: 5674 | D25: 8605 | E25: 6661 | F25: 6957 | G25: 5788 | H25: 7624 | I25: 43499 | K25: =((G25+H25)/I25) -> 0.30832893
A26: Hombre | B26: 1261 | C26: 3102 | D26: 5493 | E26: 3951 | F26: 3654 | G26: 2054 | H26: 1864 | I26: 21379 | K26: =((G26+H26)/I26) -> 0.18326395
A27: Mujer | B27: 929 | C27: 2572 | D27: 3113 | E27: 2710 | F27: 3303 | G27: 3734 | H27: 5760 | I27: 22120 | K27: =((G27+H27)/I27) -> 0.42920434
A28: Asturias
A29: Ambos Sexos | B29: 4778 | C29: 13936 | D29: 21729 | E29: 21403 | F29: 25337 | G29: 28597 | H29: 26929 | I29: 142709 | K29: =((G29+H29)/I29) -> 0.38908548
A30: Hombre | B30: 1637 | C30: 8669 | D30: 13304 | E30: 14693 | F30: 10652 | G30: 9155 | H30: 4165 | I30: 62275 | K30: =((G30+H30)/I30) -> 0.21389
A31: Mujer | B31: 3141 | C31: 5267 | D31: 8425 | E31: 6709 | F31: 14686 | G31: 19442 | H31: 22764 | I31: 80434 | K31: =((G31+H31)/I31) -> 0.52472835
A32: Ávila
A33: Ambos Sexos | B33: 798 | C33: 2525 | D33: 2541 | E33: 2870 | F33: 4101 | G33: 3003 | H33: 5094 | I33: 20933 | K33: =((G33+H33)/I33) -> 0.38680552
A34: Hombre | B34: 694 | C34: 2024 | D34: 1733 | E34: 1945 | F34: 2415 | G34: 1150 | H34: 1266 | I34: 11227 | K34: =((G34+H34)/I34) -> 0.21519551
A35: Mujer | B35: . | C35: 501 | D35: 808 | E35: 925 | F35: 1687 | G35: 1853 | H35: 3829 | I35: 9706 | K35: =((G35+H35)/I35) -> 0.58541109
A36: Badajoz
A37: Ambos Sexos | B37: 3551 | C37: 9935 | D37: 12032 | E37: 8382 | F37: 10902 | G37: 12834 | H37: 14372 | I37: 72008 | K37: =((G37+H37)/I37) -> 0.37781913
A38: Hombre | B38: 2073 | C38: 5999 | D38: 8470 | E38: 5279 | F38: 5429 | G38: 4090 | H38: 3172 | I38: 34512 | K38: =((G38+H38)/I38) -> 0.21041956
A39: Mujer | B39: 1478 | C39: 3936 | D39: 3562 | E39: 3103 | F39: 5473 | G39: 8745 | H39: 11200 | I39: 37496 | K39: =((G39+H39)/I39) -> 0.53192341
A40: Balears, Illes
A41: Ambos Sexos | B41: 4334 | C41: 22248 | D41: 27375 | E41: 16360 | F41: 14937 | G41: 15102 | H41: 12102 | I41: 112457 | K41: =((G41+H41)/I41) -> 0.2419058
A42: Hombre | B42: 916 | C42: 10723 | D42: 17571 | E42: 10478 | F42: 6158 | G42: 4916 | H42: 2987 | I42: 53749 | K42: =((G42+H42)/I42) -> 0.14703529
...

Sheet proyección hogares
A1: Proyecciones de hogares
A2: Resultados por comunidades, provincias y ciudades autónomas. Serie 2024-2039
A4: Hogares de personas residentes en viviendas familiares en España a 1 de enero, por tamaño del hogar y año
A5: Unidades: Personas, Hogares
B7: 2039 | C7: 2038 | D7: 2037 | E7: 2036 | F7: 2035 | G7: 2034 | H7: 2033 | I7: 2032 | J7: 2031 | K7: 2030 | L7: 2029 | M7: 2028 | N7: 2027 | O7: 2026 | P7: 2025 | Q7: 2024
A8: Total Nacional
A9: Total | B9: 23001927 | C9: 22838031 | D9: 22667026 | E9: 22489804 | F9: 22307244 | G9: 22118643 | H9: 21922903 | I9: 21712140 | J9: 21487754 | K9: 21244779 | L9: 20977839 | M9: 20681965 | N9: 20364411 | O9: 20026547 | P9: 19671198 | Q9: 19310776
A10: 1 persona | B10: 7708869 | C10: 7582691 | D10: 7451795 | E10: 7318562 | F10: 7183233 | G10: 7046473 | H10: 6907696 | I10: 6762485 | J10: 6615200 | K10: 6463401 | L10: 6303421 | M10: 6132953 | N10: 5961960 | O10: 5789248 | P10: 5611451 | Q10: 5433969
A11: 2 personas | B11: 7202370 | C11: 7122347 | D11: 7037709 | E11: 6947721 | F11: 6855160 | G11: 6759871 | H11: 6663567 | I11: 6561871 | J11: 6455648 | K11: 6344058 | L11: 6226729 | M11: 6101831 | N11: 5970254 | O11: 5834480 | P11: 5695627 | Q11: 5554171
A12: 3 personas | B12: 3911568 | C12: 3926621 | D12: 3941358 | E12: 3955399 | F12: 3968280 | G12: 3979504 | H12: 3988675 | I12: 3995120 | J12: 3997563 | K12: 3995309 | L12: 3988031 | M12: 3974940 | N12: 3955340 | O12: 3929228 | P12: 3899122 | Q12: 3867242
A13: 4 personas o más | B13: 4179120 | C13: 4206372 | D13: 4236164 | E13: 4268122 | F13: 4300571 | G13: 4332795 | H13: 4362965 | I13: 4392664 | J13: 4419343 | K13: 4442011 | L13: 4459658 | M13: 4472241 | N13: 4476857 | O13: 4473591 | P13: 4464998 | Q13: 4455394
A14: Tamaño medio | B14: 2.32 | C14: 2.33 | D14: 2.34 | E14: 2.35 | F14: 2.36 | G14: 2.37 | H14: 2.38 | I14: 2.4 | J14: 2.41 | K14: 2.42 | L14: 2.43 | M14: 2.45 | N14: 2.46 | O14: 2.47 | P14: 2.49 | Q14: 2.5
A15: Andalucía
A16: Total | B16: 4027872 | C16: 3998168 | D16: 3967189 | E16: 3935149 | F16: 3902257 | G16: 3868295 | H16: 3833061 | I16: 3795269 | J16: 3755318 | K16: 3712514 | L16: 3665514 | M16: 3613497 | N16: 3557773 | O16: 3499034 | P16: 3437071 | Q16: 3373700
A17: 1 persona | B17: 1329776 | C17: 1306426 | D17: 1282246 | E17: 1257728 | F17: 1232803 | G17: 1207555 | H17: 1181731 | I17: 1154689 | J17: 1127239 | K17: 1099254 | L17: 1069331 | M17: 1037113 | N17: 1004529 | O17: 971878 | P17: 937903 | Q17: 903822
A18: 2 personas | B18: 1262876 | C18: 1247265 | D18: 1230812 | E18: 1213395 | F18: 1195611 | G18: 1177277 | H18: 1158740 | I18: 1139172 | J18: 1118817 | K18: 1097358 | L18: 1074874 | M18: 1051016 | N18: 1025786 | O18: 999903 | P18: 973526 | Q18: 946351
A19: 3 personas | B19: 715490 | C19: 716738 | D19: 717875 | E19: 718773 | F19: 719462 | G19: 719850 | H19: 719962 | I19: 719626 | J19: 718628 | K19: 716845 | L19: 714348 | M19: 710975 | N19: 706655 | O19: 701234 | P19: 695282 | Q19: 689011
A20: 4 personas o más | B20: 719730 | C20: 727739 | D20: 736256 | E20: 745253 | F20: 754381 | G20: 763613 | H20: 772628 | I20: 781782 | J20: 790634 | K20: 799057 | L20: 806961 | M20: 814393 | N20: 820803 | O20: 826019 | P20: 830360 | Q20: 834516
A21: Tamaño medio | B21: 2.3 | C21: 2.31 | D21: 2.33 | E21: 2.34 | F21: 2.35 | G21: 2.37 | H21: 2.38 | I21: 2.4 | J21: 2.42 | K21: 2.43 | L21: 2.45 | M21: 2.47 | N21: 2.49 | O21: 2.51 | P21: 2.52 | Q21: 2.54
A22: Málaga
A23: Total | B23: 910811 | C23: 901533 | D23: 891947 | E23: 882094 | F23: 871931 | G23: 861388 | H23: 850328 | I23: 838417 | J23: 825684 | K23: 811873 | L23: 796629 | M23: 779738 | N23: 761251 | O23: 741414 | P23: 720380 | Q23: 698969
A24: 1 persona | B24: 294550 | C24: 289278 | D24: 283841 | E24: 278311 | F24: 272672 | G24: 266932 | H24: 261051 | I24: 254835 | J24: 248477 | K24: 241904 | L24: 234873 | M24: 227312 | N24: 219425 | O24: 211338 | P24: 202935 | Q24: 194560
A25: 2 personas | B25: 286802 | C25: 282451 | D25: 277932 | E25: 273268 | F25: 268487 | G25: 263581 | H25: 258524 | I25: 253200 | J25: 247645 | K25: 241784 | L25: 235561 | M25: 228923 | N25: 221804 | O25: 214393 | P25: 206725 | Q25: 198926
A26: 3 personas | B26: 162765 | C26: 162208 | D26: 161608 | E26: 160949 | F26: 160224 | G26: 159396 | H26: 158454 | I26: 157355 | J26: 156026 | K26: 154424 | L26: 152535 | M26: 150307 | N26: 147724 | O26: 144770 | P26: 141558 | Q26: 138234
A27: 4 personas o más | B27: 166694 | C27: 167596 | D27: 168566 | E27: 169566 | F27: 170548 | G27: 171479 | H27: 172299 | I27: 173027 | J27: 173536 | K27: 173761 | L27: 173660 | M27: 173196 | N27: 172298 | O27: 170913 | P27: 169162 | Q27: 167249
A28: Tamaño medio | B28: 2.34 | C28: 2.35 | D28: 2.36 | E28: 2.37 | F28: 2.39 | G28: 2.4 | H28: 2.41 | I28: 2.42 | J28: 2.43 | K28: 2.45 | L28: 2.46 | M28: 2.47 | N28: 2.48 | O28: 2.5 | P28: 2.51 | Q28: 2.52
A29: Jaén
A30: Total | B30: 265031 | C30: 264690 | D30: 264318 | E30: 263834 | F30: 263323 | G30: 262783 | H30: 262133 | I30: 261346 | J30: 260560 | K30: 259648 | L30: 258498 | M30: 257094 | N30: 255631 | O30: 254179 | P30: 252484 | Q30: 250644
A31: 1 persona | B31: 94569 | C31: 93228 | D31: 91904 | E31: 90517 | F31: 89152 | G31: 87784 | H31: 86316 | I31: 84765 | J31: 83312 | K31: 81807 | L31: 80088 | M31: 78173 | N31: 76335 | O31: 74595 | P31: 72644 | Q31: 70607
A32: 2 personas | B32: 87822 | C32: 87339 | D32: 86777 | E32: 86101 | F32: 85348 | G32: 84553 | H32: 83720 | I32: 82783 | J32: 81766 | K32: 80663 | L32: 79499 | M32: 78242 | N32: 76876 | O32: 75514 | P32: 74055 | Q32: 72486
A33: 3 personas | B33: 42969 | C33: 43482 | D33: 43989 | E33: 44489 | F33: 44980 | G33: 45462 | H33: 45950 | I33: 46423 | J33: 46858 | K33: 47272 | L33: 47684 | M33: 48079 | N33: 48442 | O33: 48749 | P33: 49068 | Q33: 49378
A34: 4 personas o más | B34: 39671 | C34: 40641 | D34: 41648 | E34: 42727 | F34: 43843 | G34: 44984 | H34: 46147 | I34: 47375 | J34: 48624 | K34: 49906 | L34: 51227 | M34: 52600 | N34: 53978 | O34: 55321 | P34: 56717 | Q34: 58173
A35: Tamaño medio | B35: 2.16 | C35: 2.17 | D35: 2.19 | E35: 2.21 | F35: 2.22 | G35: 2.24 | H35: 2.26 | I35: 2.28 | J35: 2.3 | K35: 2.32 | L35: 2.34 | M35: 2.36 | N35: 2.39 | O35: 2.41 | P35: 2.43 | Q35: 2.46
A36: Almería
A37: Total | B37: 388496 | C37: 383658 | D37: 378731 | E37: 373730 | F37: 368657 | G37: 363494 | H37: 358176 | I37: 352584 | J37: 346662 | K37: 340318 | L37: 333451 | M37: 325916 | N37: 317844 | O37: 309237 | P37: 300305 | Q37: 291239
A38: 1 persona | B38: 123442 | C38: 120874 | D38: 118267 | E38: 115681 | F38: 113077 | G38: 110483 | H38: 107855 | I38: 105144 | J38: 102360 | K38: 99486 | L38: 96480 | M38: 93244 | N38: 89954 | O38: 86578 | P38: 83189 | Q38: 79818
A39: 2 personas | B39: 116034 | C39: 114060 | D39: 112026 | E39: 109904 | F39: 107773 | G39: 105618 | H39: 103442 | I39: 101195 | J39: 98859 | K39: 96415 | L39: 93842 | M39: 91105 | N39: 88239 | O39: 85252 | P39: 82233 | Q39: 79162
A40: 3 personas | B40: 67574 | C40: 67277 | D40: 66964 | E40: 66625 | F40: 66258 | G40: 65853 | H40: 65403 | I40: 64893 | J40: 64298 | K40: 63597 | L40: 62781 | M40: 61832 | N40: 60747 | O40: 59520 | P40: 58197 | Q40: 56832
A41: 4 personas o más | B41: 81446 | C41: 81447 | D41: 81474 | E41: 81520 | F41: 81549 | G41: 81540 | H41: 81476 | I41: 81352 | J41: 81145 | K41: 80820 | L41: 80348 | M41: 79735 | N41: 78904 | O41: 77887 | P41: 76686 | Q41: 75427
A42: Tamaño medio | B42: 2.43 | C42: 2.44 | D42: 2.45 | E42: 2.46 | F42: 2.47 | G42: 2.48 | H42: 2.5 | I42: 2.51 | J42: 2.52 | K42: 2.53 | L42: 2.54 | M42: 2.56 | N42: 2.57 | O42: 2.58 | P42: 2.59 | Q42: 2.6
...
